Workbook

Sheet emp_data
A1: Emp_ID | B1: Emp_Name | C1: Gender | D1: Department | E1: Designation | F1: Location | G1: Join_Date | H1: DOB | I1: Basic_Salary | J1: Allowance | K1: Bonus | L1: Gross | M1: Annual Salary | N1: % Bonus | O1: Experience_Years | P1: Attendance_% | Q1: Rating | R1: Training_Hours | S1: Leave_Days | T1: Performance_Score | V1: Attrition_Status | W1: Promotion_Status | X1: Manager
A2: E1001 | B2: Priya S | C2: Male | D2: Sales | E2: Executive | F2: Chennai | G2: 45439 | H2: 29846 | I2: 74692 | J2: 11785 | K2: 10213 | L2: =SUM(I2:K2) -> 96690 | M2: =L2*12 -> 1160280 | N2: =K2/I2 -> 0.13673486 | O2: 11 | P2: 90 | Q2: 1 | R2: 20 | S2: 4 | T2: 71 | V2: No | W2: No | X2: Manoj P
A3: E1002 | B3: Anitha R | C3: Male | D3: Sales | E3: Analyst | F3: Hyderabad | G3: 43551 | H3: 30365 | I3: 25864 | J3: 8168 | K3: 12993 | L3: =SUM(I3:K3) -> 47025 | M3: =L3*12 -> 564300 | N3: =K3/I3 -> 0.50235849 | O3: 15 | P3: 83 | Q3: 1 | R3: 11 | S3: 21 | T3: 59 | V3: No | W3: No | X3: Ravi Kumar
A4: E1003 | B4: Meena M | C4: Female | D4: Finance | E4: Team Lead | F4: Chennai | G4: 45153 | H4: 34219 | I4: 70018 | J4: 11547 | K4: 14131 | L4: =SUM(I4:K4) -> 95696 | M4: =L4*12 -> 1148352 | N4: =K4/I4 -> 0.20181953 | O4: 16 | P4: 86 | Q4: 5 | R4: 67 | S4: 18 | T4: 70 | V4: Yes | W4: No | X4: Divya R
A5: E1004 | B5: Manoj M | C5: Female | D5: Marketing | E5: Associate | F5: Bengaluru | G5: 43539 | H5: 37577 | I5: 29173 | J5: 16882 | K5: 13356 | L5: =SUM(I5:K5) -> 59411 | M5: =L5*12 -> 712932 | N5: =K5/I5 -> 0.45782059 | O5: 6 | P5: 82 | Q5: 4 | R5: 33 | S5: 5 | T5: 71 | V5: No | W5: No | X5: Karthik V
A6: E1005 | B6: Kumar K | C6: Female | D6: Sales | E6: Manager | F6: Madurai | G6: 42071 | H6: 32318 | I6: 36554 | J6: 16624 | K6: 11294 | L6: =SUM(I6:K6) -> 64472 | M6: =L6*12 -> 773664 | N6: =K6/I6 -> 0.30896755 | O6: 12 | P6: 80 | Q6: 3 | R6: 29 | S6: 12 | T6: 84 | V6: No | W6: No | X6: Priya M
A7: E1006 | B7: Priya V | C7: Female | D7: Sales | E7: Associate | F7: Mumbai | G7: 42960 | H7: 38136 | I7: 88414 | J7: 5909 | K7: 3519 | L7: =SUM(I7:K7) -> 97842 | M7: =L7*12 -> 1174104 | N7: =K7/I7 -> 0.039801389 | O7: 18 | P7: 94 | Q7: 4 | R7: 59 | S7: 1 | T7: 50 | V7: No | W7: No | X7: Divya R
A8: E1007 | B8: Vijay K | C8: Female | D8: Finance | E8: Associate | F8: Madurai | G8: 43783 | H8: 36108 | I8: 25046 | J8: 4779 | K8: 11118 | L8: =SUM(I8:K8) -> 40943 | M8: =L8*12 -> 491316 | N8: =K8/I8 -> 0.44390322 | O8: 3 | P8: 96 | Q8: 3 | R8: 11 | S8: 2 | T8: 77 | V8: Yes | W8: No | X8: Karthik V
A9: E1008 | B9: Kumar K | C9: Female | D9: IT | E9: Executive | F9: Madurai | G9: 43940 | H9: 29762 | I9: 98608 | J9: 8485 | K9: 7784 | L9: =SUM(I9:K9) -> 114877 | M9: =L9*12 -> 1378524 | N9: =K9/I9 -> 0.078938828 | O9: 12 | P9: 80 | Q9: 2 | R9: 53 | S9: 2 | T9: 95 | V9: No | W9: No | X9: Manoj P
A10: E1009 | B10: Anitha V | C10: Male | D10: Operations | E10: Analyst | F10: Hyderabad | G10: 43591 | H10: 38027 | I10: 65129 | J10: 5394 | K10: 11746 | L10: =SUM(I10:K10) -> 82269 | M10: =L10*12 -> 987228 | N10: =K10/I10 -> 0.18034977 | O10: 10 | P10: 92 | Q10: 3 | R10: 16 | S10: 17 | T10: 71 | V10: No | W10: No | X10: Ravi Kumar
A11: E1010 | B11: Sneha P | C11: Female | D11: Sales | E11: Analyst | F11: Mumbai | G11: 42562 | H11: 36671 | I11: 27701 | J11: 8726 | K11: 8368 | L11: =SUM(I11:K11) -> 44795 | M11: =L11*12 -> 537540 | N11: =K11/I11 -> 0.30208296 | O11: 15 | P11: 89 | Q11: 4 | R11: 3 | S11: 5 | T11: 83 | V11: No | W11: No | X11: Karthik V
A12: E1011 | B12: Manoj P | C12: Male | D12: Finance | E12: Manager | F12: Chennai | G12: 44239 | H12: 35266 | I12: 54478 | J12: 17638 | K12: 10341 | L12: =SUM(I12:K12) -> 82457 | M12: =L12*12 -> 989484 | N12: =K12/I12 -> 0.18981974 | O12: 11 | P12: 82 | Q12: 3 | R12: 64 | S12: 7 | T12: 63 | V12: No | W12: No | X12: Manoj P
A13: E1012 | B13: Kumar K | C13: Male | D13: HR | E13: Manager | F13: Coimbatore | G13: 45110 | H13: 29502 | I13: 50449 | J13: 7395 | K13: 10250 | L13: =SUM(I13:K13) -> 68094 | M13: =L13*12 -> 817128 | N13: =K13/I13 -> 0.20317548 | O13: 8 | P13: 82 | Q13: 5 | R13: 40 | S13: 2 | T13: 71 | V13: No | W13: No | X13: Karthik V
... A201: E1200 | B201: Meena K | C201: Female | D201: HR | E201: Executive | F201: Madurai | G201: 43919 | H201: 38179 | I201: 45790 | J201: 13925 | K201: 1992 | L201: =SUM(I201:K201) -> 61707 | M201: =L201*12 -> 740484 | N201: =K201/I201 -> 0.043502948 | O201: 19 | P201: 94 | Q201: 2 | R201: 39 | S201: 24 | T201: 82 | V201: No | W201: No | X201: Manoj P

Sheet Sheet2
A1: 1 | B1: How many employees are currently working in the organization? | C1: =COUNTA(emp_data!A2:A201) -> 200
A2: =A1+1 -> 2 | B2: Identify the total number of departments in the company. | C2: =COUNTA(_xlfn.UNIQUE(emp_data!D2:D201)) -> 6
A3: =A2+1 -> 3 | B3: List all unique job roles available in the organization. | C3: {=_xlfn.UNIQUE(emp_data!E2:E201)} -> Executive
C4: Analyst
C5: Team Lead
C6: Associate
C7: Manager
C8: Senior Analyst
A9: 4 | B9: Which department has the highest number of employees? | C9: {=_xlfn.LET( _xlpm.Dept,emp_data!D2:D201, _xlpm.UniqueDept,_xlfn.UNIQUE(_xlpm.Dept), _xlpm.DeptCount,COUNTIF(_xlpm.Dept,_xlpm.UniqueDept), INDEX(_xlpm.UniqueDept,MATCH(MAX(_xlpm.DeptCount),_xlpm.DeptCount,0)) )} -> Finance
A10: 5 | B10: Which manager supervises the largest team? | C10: {=_xlfn.LET( _xlpm.Manager,emp_data!X2:X201, _xlpm.UniqueManager,_xlfn.UNIQUE(_xlpm.Manager), _xlpm.TeamCount,COUNTIF(_xlpm.Manager,_xlpm.UniqueManager), INDEX(_xlpm.UniqueManager,MATCH(MAX(_xlpm.TeamCount),_xlpm.TeamCount,0)) )} -> Priya M
A11: 6 | B11: Find the employee who joined the organization most recently. | C11: =_xlfn.XLOOKUP(MAX(emp_data!G2:G201), emp_data!G2:G201, emp_data!A2:A201) -> E1085
A12: 7 | B12: Identify the oldest employee in the company. | C12: =_xlfn.XLOOKUP(MIN(emp_data!H2:H201), emp_data!H2:H201, emp_data!A2:A201) -> E1064
A13: 8 | B13: Determine the location having the maximum number of employees. | C13: {=_xlfn.LET(_xlpm.loc,emp_data!F2:F201,_xlpm.u,_xlfn.UNIQUE(_xlpm.loc),_xlpm.cnt,COUNTIF(_xlpm.loc,_xlpm.u),INDEX(_xlpm.u,MATCH(MAX(_xlpm.cnt),_xlpm.cnt,0)))} -> Chennai
A15: 9 | B15: Calculate the Gross Salary of every employee.
A16: 10 | B16: Gross Salary = Basic Salary + Allowance + Bonus
A17: 11 | B17: Calculate the Annual Salary of each employee.
A18: 12 | B18: Calculate the percentage of Bonus received by each employee with respect to their Basic Salary.
A19: 13 | B19: Identify employees receiving the highest bonus. | C19: =_xlfn.LET( _xlpm.Bonus,emp_data!K2:K201, _xlpm.EmpName,emp_data!B2:B201, INDEX(_xlpm.EmpName,MATCH(MAX(_xlpm.Bonus),_xlpm.Bonus,0)) ) -> Kumar K
A20: 14 | B20: Calculate the total monthly payroll of the organization. | C20: =SUM(emp_data!L2:L201) -> 15607372
A21: 15 | B21: Determine the average salary paid to employees. | C21: =SUM(emp_data!L2:L201)/COUNTA(emp_data!A2:A201) -> 78036.86
A22: 16 | B22: Find the highest and lowest salary in the organization.
A23: 17 | B23: Calculate the total amount spent on employee bonuses.
A24: 18 | B24: Calculate the total employee allowances paid.
A25: 19 | B25: Identify employees earning above the organization's average salary. | C25: {=_xlfn._xlws.FILTER(emp_data!A2:X201,emp_data!L2:L201>AVERAGE(emp_data!L2:L201))} -> E1001 | D25: Priya S | E25: Male | F25: Sales | G25: Executive | H25: Chennai | I25: 45439 | J25: 29846 | K25: 74692 | L25: 11785 | M25: 10213 | N25: 96690 | O25: 1160280 | P25: 0.13673486 | Q25: 11 | R25: 90 | S25: 1 | T25: 20 | U25: 4 | V25: 71 | W25: 0 | X25: No | Y25: No | Z25: Manoj P
C26: E1003 | D26: Meena M | E26: Female | F26: Finance | G26: Team Lead | H26: Chennai | I26: 45153 | J26: 34219 | K26: 70018 | L26: 11547 | M26: 14131 | N26: 95696 | O26: 1148352 | P26: 0.20181953 | Q26: 16 | R26: 86 | S26: 5 | T26: 67 | U26: 18 | V26: 70 | W26: 0 | X26: Yes | Y26: No | Z26: Divya R
C27: E1006 | D27: Priya V | E27: Female | F27: Sales | G27: Associate | H27: Mumbai | I27: 42960 | J27: 38136 | K27: 88414 | L27: 5909 | M27: 3519 | N27: 97842 | O27: 1174104 | P27: 0.039801389 | Q27: 18 | R27: 94 | S27: 4 | T27: 59 | U27: 1 | V27: 50 | W27: 0 | X27: No | Y27: No | Z27: Divya R
C28: E1008 | D28: Kumar K | E28: Female | F28: IT | G28: Executive | H28: Madurai | I28: 43940 | J28: 29762 | K28: 98608 | L28: 8485 | M28: 7784 | N28: 114877 | O28: 1378524 | P28: 0.078938828 | Q28: 12 | R28: 80 | S28: 2 | T28: 53 | U28: 2 | V28: 95 | W28: 0 | X28: No | Y28: No | Z28: Manoj P
C29: E1009 | D29: Anitha V | E29: Male | F29: Operations | G29: Analyst | H29: Hyderabad | I29: 43591 | J29: 38027 | K29: 65129 | L29: 5394 | M29: 11746 | N29: 82269 | O29: 987228 | P29: 0.18034977 | Q29: 10 | R29: 92 | S29: 3 | T29: 16 | U29: 17 | V29: 71 | W29: 0 | X29: No | Y29: No | Z29: Ravi Kumar
C30: E1011 | D30: Manoj P | E30: Male | F30: Finance | G30: Manager | H30: Chennai | I30: 44239 | J30: 35266 | K30: 54478 | L30: 17638 | M30: 10341 | N30: 82457 | O30: 989484 | P30: 0.18981974 | Q30: 11 | R30: 82 | S30: 3 | T30: 64 | U30: 7 | V30: 63 | W30: 0 | X30: No | Y30: No | Z30: Manoj P
C31: E1013 | D31: Rahul P | E31: Male | F31: Sales | G31: Team Lead | H31: Mumbai | I31: 43636 | J31: 29683 | K31: 58666 | L31: 14694 | M31: 14644 | N31: 88004 | O31: 1056048 | P31: 0.24961647 | Q31: 19 | R31: 95 | S31: 3 | T31: 50 | U31: 7 | V31: 82 | W31: 0 | X31: No | Y31: No | Z31: Karthik V
C32: E1014 | D32: Arjun P | E32: Female | F32: Finance | G32: Associate | H32: Hyderabad | I32: 42506 | J32: 30080 | K32: 72270 | L32: 17117 | M32: 8549 | N32: 97936 | O32: 1175232 | P32: 0.11829251 | Q32: 12 | R32: 93 | S32: 3 | T32: 45 | U32: 6 | V32: 99 | W32: 0 | X32: No | Y32: No | Z32: Manoj P
C33: E1016 | D33: Ravi K | E33: Female | F33: IT | G33: Manager | H33: Bengaluru | I33: 43227 | J33: 30981 | K33: 86020 | L33: 12396 | M33: 13543 | N33: 111959 | O33: 1343508 | P33: 0.15744013 | Q33: 11 | R33: 87 | S33: 4 | T33: 34 | U33: 14 | V33: 86 | W33: 0 | X33: No | Y33: No | Z33: Manoj P
C34: E1018 | D34: Rahul S | E34: Female | F34: HR | G34: Manager | H34: Chennai | I34: 43903 | J34: 37480 | K34: 62841 | L34: 14562 | M34: 10504 | N34: 87907 | O34: 1054884 | P34: 0.16715202 | Q34: 1 | R34: 90 | S34: 4 | T34: 29 | U34: 22 | V34: 54 | W34: 0 | X34: No | Y34: No | Z34: Manoj P
C35: E1023 | D35: Anitha M | E35: Male | F35: Marketing | G35: Associate | H35: Bengaluru | I35: 43605 | J35: 32316 | K35: 76129 | L35: 4262 | M35: 9141 | N35: 89532 | O35: 1074384 | P35: 0.12007251 | Q35: 2 | R35: 89 | S35: 2 | T35: 60 | U35: 23 | V35: 96 | W35: 0 | X35: Yes | Y35: No | Z35: Lakshmi S
C36: E1024 | D36: Divya M | E36: Female | F36: Marketing | G36: Manager | H36: Chennai | I36: 43827 | J36: 37754 | K36: 71269 | L36: 7730 | M36: 6943 | N36: 85942 | O36: 1031304 | P36: 0.097419635 | Q36: 7 | R36: 92 | S36: 1 | T36: 13 | U36: 16 | V36: 98 | W36: 0 | X36: Yes | Y36: No | Z36: Karthik V
C37: E1027 | D37: Pooja S | E37: Male | F37: IT | G37: Associate | H37: Chennai | I37: 43199 | J37: 34584 | K37: 77522 | L37: 8661 | M37: 13892 | N37: 100075 | O37: 1200900 | P37: 0.17920074 | Q37: 8 | R37: 81 | S37: 1 | T37: 70 | U37: 2 | V37: 57 | W37: 0 | X37: No | Y37: No | Z37: Manoj P
... C118: E1199 | D118: Nisha M | E118: Female | F118: HR | G118: Senior Analyst | H118: Madurai | I118: 45524 | J118: 31983 | K118: 83226 | L118: 4643 | M118: 3808 | N118: 91677 | O118: 1100124 | P118: 0.045754932 | Q118: 10 | R118: 87 | S118: 2 | T118: 30 | U118: 19 | V118: 78 | W118: 0 | X118: No | Y118: No | Z118: Divya R
A119: 20 | B119: Calculate the average performance score of employees. | C119: =AVERAGE(emp_data!T2:T201) -> 75.735
A120: 21 | B120: Identify the employee with the highest performance score. | C120: =_xlfn.LET( _xlpm.Score,emp_data!T2:T201, _xlpm.EmpName,emp_data!B2:B201, INDEX(_xlpm.EmpName,MATCH(MAX(_xlpm.Score),_xlpm.Score,0)) ) -> Asha K
A121: 22 | B121: Identify the employee with the lowest performance score. | C121: =_xlfn.LET( _xlpm.Score,emp_data!T2:T201, _xlpm.EmpName,emp_data!B2:B201, INDEX(_xlpm.EmpName,MATCH(MIN(_xlpm.Score),_xlpm.Score,0)) ) -> Priya V
...

Sheet Q01
A1: 1 | B1: How many employees are currently working in the organization? | C1: =COUNTA(emp_data!A2:A201) -> 200
C3: =COUNTA(emp_data!B2:B201) -> 200

Sheet Q02
A1: 2 | B1: Identify the total number of departments in the company. | C1: =COUNTA(_xlfn.UNIQUE(emp_data!D2:D201)) -> 6
C3: =COUNTA(_xlfn.UNIQUE(emp_data!D2:D201)) -> 6

Sheet Q03
A1: 3 | B1: List all unique job roles available in the organization. | C1: {=_xlfn.UNIQUE(emp_data!E2:E201)} -> Executive
C2: Analyst
C3: Team Lead
C4: Associate
C5: Manager
C6: Senior Analyst

Sheet Q04
A1: 4 | B1: Which department has the highest number of employees? | C1: {=_xlfn.LET( _xlpm.Dept,emp_data!D2:D201, _xlpm.UniqueDept,_xlfn.UNIQUE(_xlpm.Dept), _xlpm.DeptCount,COUNTIF(_xlpm.Dept,_xlpm.UniqueDept), INDEX(_xlpm.UniqueDept,MATCH(MAX(_xlpm.DeptCount),_xlpm.DeptCount,0)) )} -> Finance
E2: .=LET(dept,emp_data!D2:D201,Uniquedept,UNIQUE(dept),deptcount,COUNTIF(dept,UniqueDept),INDEX(Uniquedept),MATCH(MAX(deptcount),deptcount,0))
E4: =LET(
E5: Dept,emp_data!D2:D201,
E6: UniqueDept,UNIQUE(Dept),
E7: DeptCount,COUNTIF(Dept,UniqueDept),
E8: INDEX(UniqueDept,MATCH(MAX(DeptCount),DeptCount,0))
E9: )

Sheet Q05
A1: 5 | B1: Which manager supervises the largest team? | C1: {=_xlfn.LET( _xlpm.Manager,emp_data!X2:X201, _xlpm.UniqueManager,_xlfn.UNIQUE(_xlpm.Manager), _xlpm.TeamCount,COUNTIF(_xlpm.Manager,_xlpm.UniqueManager), INDEX(_xlpm.UniqueManager,MATCH(MAX(_xlpm.TeamCount),_xlpm.TeamCount,0)) )} -> Priya M

Sheet Q06
A1: 6 | B1: Find the employee who joined the organization most recently. | C1: =_xlfn.XLOOKUP(MAX(emp_data!G2:G201), emp_data!G2:G201, emp_data!A2:A201) -> E1085
C3: =_xlfn.XLOOKUP(MAX(emp_data!G2:G201),emp_data!G2:G201,emp_data!A2:A201) -> E1085

Sheet Q07
A1: 7 | B1: Identify the oldest employee in the company. | C1: =_xlfn.XLOOKUP(MIN(emp_data!H2:H201), emp_data!H2:H201, emp_data!A2:A201) -> E1064
C3: =_xlfn.XLOOKUP(MIN(emp_data!H2:H201),emp_data!H2:H201,emp_data!A2:A201) -> E1064

Sheet Q08
A1: 8 | B1: Determine the location having the maximum number of employees. | C1: {=_xlfn.LET(_xlpm.loc,emp_data!F2:F201,_xlpm.u,_xlfn.UNIQUE(_xlpm.loc),_xlpm.cnt,COUNTIF(_xlpm.loc,_xlpm.u),INDEX(_xlpm.u,MATCH(MAX(_xlpm.cnt),_xlpm.cnt,0)))} -> Chennai

Sheet Q09
A1: 9 | B1: Calculate the Gross Salary of every employee. | C1: Added in the data sheet - Column L
C3: SALARY + BONUS
C4: =SUM(emp_data!L189:L201) -> 965929

Sheet Q10
A1: 10 | B1: Gross Salary = Basic Salary + Allowance + Bonus

Sheet Q11
A1: 11 | B1: Calculate the Annual Salary of each employee. | C1: Added in the data sheet : Column M
C3: GROSS *12

Sheet Q12
A1: 12 | B1: Calculate the percentage of Bonus received by each employee with respect to their Basic Salary. | C1: Added in the data sheet column N

Sheet Q13
A1: 13 | B1: Identify employees receiving the highest bonus. | C1: =_xlfn.LET( _xlpm.Bonus,emp_data!K2:K201, _xlpm.EmpName,emp_data!B2:B201, INDEX(_xlpm.EmpName,MATCH(MAX(_xlpm.Bonus),_xlpm.Bonus,0)) ) -> Kumar K

Sheet Q14
A1: 14 | B1: Calculate the total monthly payroll of the organization. | C1: =SUM(emp_data!L2:L201) -> 15607372

Sheet Q15
A1: 15 | B1: Determine the average salary paid to employees. | C1: =SUM(emp_data!L2:L201)/COUNTA(emp_data!A2:A201) -> 78036.86

Sheet Q16
A1: 16 | B1: Find the highest and lowest salary in the organization.
B2: Highest Annual Salary | C2: =MAX(emp_data!M2:M201) -> 1462308
B3: Lowest Annual Salary | C3: =MIN(emp_data!M2:M201) -> 491316

Sheet Q17
A1: 17 | B1: Calculate the total amount spent on employee bonuses. | C1: =SUM(emp_data!K2:K201) -> 1550106

Sheet Q18
A1: 18 | B1: Calculate the total employee allowances paid. | C1: =SUM(emp_data!J2:J201) -> 1982867

Sheet Q19
A1: 19 | B1: Identify employees earning above the organization's average salary. | C1: {=_xlfn._xlws.FILTER(emp_data!A2:X201,emp_data!L2:L201>AVERAGE(emp_data!L2:L201))} -> E1001 | D1: Priya S | E1: Male | F1: Sales | G1: Executive | H1: Chennai | I1: 45439 | J1: 29846 | K1: 74692 | L1: 11785 | M1: 10213 | N1: 96690 | O1: 1160280 | P1: 0.13673486 | Q1: 11 | R1: 90 | S1: 1 | T1: 20 | U1: 4 | V1: 71 | W1: 0 | X1: No | Y1: No | Z1: Manoj P | AC1: {=_xlfn._xlws.FILTER(emp_data!A2:X201,emp_data!L2:L201>AVERAGE(emp_data!L2:L201))} -> E1001 | AD1: Priya S | AE1: Male | AF1: Sales | AG1: Executive | AH1: Chennai | AI1: 45439 | AJ1: 29846 | AK1: 74692 | AL1: 11785 | AM1: 10213 | AN1: 96690 | AO1: 1160280 | AP1: 0.13673486 | AQ1: 11 | AR1: 90 | AS1: 1 | AT1: 20 | AU1: 4 | AV1: 71 | AW1: 0 | AX1: No | AY1: No | AZ1: Manoj P
C2: E1003 | D2: Meena M | E2: Female | F2: Finance | G2: Team Lead | H2: Chennai | I2: 45153 | J2: 34219 | K2: 70018 | L2: 11547 | M2: 14131 | N2: 95696 | O2: 1148352 | P2: 0.20181953 | Q2: 16 | R2: 86 | S2: 5 | T2: 67 | U2: 18 | V2: 70 | W2: 0 | X2: Yes | Y2: No | Z2: Divya R | AC2: E1003 | AD2: Meena M | AE2: Female | AF2: Finance | AG2: Team Lead | AH2: Chennai | AI2: 45153 | AJ2: 34219 | AK2: 70018 | AL2: 11547 | AM2: 14131 | AN2: 95696 | AO2: 1148352 | AP2: 0.20181953 | AQ2: 16 | AR2: 86 | AS2: 5 | AT2: 67 | AU2: 18 | AV2: 70 | AW2: 0 | AX2: Yes | AY2: No | AZ2: Divya R
C3: E1006 | D3: Priya V | E3: Female | F3: Sales | G3: Associate | H3: Mumbai | I3: 42960 | J3: 38136 | K3: 88414 | L3: 5909 | M3: 3519 | N3: 97842 | O3: 1174104 | P3: 0.039801389 | Q3: 18 | R3: 94 | S3: 4 | T3: 59 | U3: 1 | V3: 50 | W3: 0 | X3: No | Y3: No | Z3: Divya R | AC3: E1006 | AD3: Priya V | AE3: Female | AF3: Sales | AG3: Associate | AH3: Mumbai | AI3: 42960 | AJ3: 38136 | AK3: 88414 | AL3: 5909 | AM3: 3519 | AN3: 97842 | AO3: 1174104 | AP3: 0.039801389 | AQ3: 18 | AR3: 94 | AS3: 4 | AT3: 59 | AU3: 1 | AV3: 50 | AW3: 0 | AX3: No | AY3: No | AZ3: Divya R
C4: E1008 | D4: Kumar K | E4: Female | F4: IT | G4: Executive | H4: Madurai | I4: 43940 | J4: 29762 | K4: 98608 | L4: 8485 | M4: 7784 | N4: 114877 | O4: 1378524 | P4: 0.078938828 | Q4: 12 | R4: 80 | S4: 2 | T4: 53 | U4: 2 | V4: 95 | W4: 0 | X4: No | Y4: No | Z4: Manoj P | AC4: E1008 | AD4: Kumar K | AE4: Female | AF4: IT | AG4: Executive | AH4: Madurai | AI4: 43940 | AJ4: 29762 | AK4: 98608 | AL4: 8485 | AM4: 7784 | AN4: 114877 | AO4: 1378524 | AP4: 0.078938828 | AQ4: 12 | AR4: 80 | AS4: 2 | AT4: 53 | AU4: 2 | AV4: 95 | AW4: 0 | AX4: No | AY4: No | AZ4: Manoj P
C5: E1009 | D5: Anitha V | E5: Male | F5: Operations | G5: Analyst | H5: Hyderabad | I5: 43591 | J5: 38027 | K5: 65129 | L5: 5394 | M5: 11746 | N5: 82269 | O5: 987228 | P5: 0.18034977 | Q5: 10 | R5: 92 | S5: 3 | T5: 16 | U5: 17 | V5: 71 | W5: 0 | X5: No | Y5: No | Z5: Ravi Kumar | AC5: E1009 | AD5: Anitha V | AE5: Male | AF5: Operations | AG5: Analyst | AH5: Hyderabad | AI5: 43591 | AJ5: 38027 | AK5: 65129 | AL5: 5394 | AM5: 11746 | AN5: 82269 | AO5: 987228 | AP5: 0.18034977 | AQ5: 10 | AR5: 92 | AS5: 3 | AT5: 16 | AU5: 17 | AV5: 71 | AW5: 0 | AX5: No | AY5: No | AZ5: Ravi Kumar
C6: E1011 | D6: Manoj P | E6: Male | F6: Finance | G6: Manager | H6: Chennai | I6: 44239 | J6: 35266 | K6: 54478 | L6: 17638 | M6: 10341 | N6: 82457 | O6: 989484 | P6: 0.18981974 | Q6: 11 | R6: 82 | S6: 3 | T6: 64 | U6: 7 | V6: 63 | W6: 0 | X6: No | Y6: No | Z6: Manoj P | AC6: E1011 | AD6: Manoj P | AE6: Male | AF6: Finance | AG6: Manager | AH6: Chennai | AI6: 44239 | AJ6: 35266 | AK6: 54478 | AL6: 17638 | AM6: 10341 | AN6: 82457 | AO6: 989484 | AP6: 0.18981974 | AQ6: 11 | AR6: 82 | AS6: 3 | AT6: 64 | AU6: 7 | AV6: 63 | AW6: 0 | AX6: No | AY6: No | AZ6: Manoj P
C7: E1013 | D7: Rahul P | E7: Male | F7: Sales | G7: Team Lead | H7: Mumbai | I7: 43636 | J7: 29683 | K7: 58666 | L7: 14694 | M7: 14644 | N7: 88004 | O7: 1056048 | P7: 0.24961647 | Q7: 19 | R7: 95 | S7: 3 | T7: 50 | U7: 7 | V7: 82 | W7: 0 | X7: No | Y7: No | Z7: Karthik V | AC7: E1013 | AD7: Rahul P | AE7: Male | AF7: Sales | AG7: Team Lead | AH7: Mumbai | AI7: 43636 | AJ7: 29683 | AK7: 58666 | AL7: 14694 | AM7: 14644 | AN7: 88004 | AO7: 1056048 | AP7: 0.24961647 | AQ7: 19 | AR7: 95 | AS7: 3 | AT7: 50 | AU7: 7 | AV7: 82 | AW7: 0 | AX7: No | AY7: No | AZ7: Karthik V
C8: E1014 | D8: Arjun P | E8: Female | F8: Finance | G8: Associate | H8: Hyderabad | I8: 42506 | J8: 30080 | K8: 72270 | L8: 17117 | M8: 8549 | N8: 97936 | O8: 1175232 | P8: 0.11829251 | Q8: 12 | R8: 93 | S8: 3 | T8: 45 | U8: 6 | V8: 99 | W8: 0 | X8: No | Y8: No | Z8: Manoj P | AC8: E1014 | AD8: Arjun P | AE8: Female | AF8: Finance | AG8: Associate | AH8: Hyderabad | AI8: 42506 | AJ8: 30080 | AK8: 72270 | AL8: 17117 | AM8: 8549 | AN8: 97936 | AO8: 1175232 | AP8: 0.11829251 | AQ8: 12 | AR8: 93 | AS8: 3 | AT8: 45 | AU8: 6 | AV8: 99 | AW8: 0 | AX8: No | AY8: No | AZ8: Manoj P
C9: E1016 | D9: Ravi K | E9: Female | F9: IT | G9: Manager | H9: Bengaluru | I9: 43227 | J9: 30981 | K9: 86020 | L9: 12396 | M9: 13543 | N9: 111959 | O9: 1343508 | P9: 0.15744013 | Q9: 11 | R9: 87 | S9: 4 | T9: 34 | U9: 14 | V9: 86 | W9: 0 | X9: No | Y9: No | Z9: Manoj P | AC9: E1016 | AD9: Ravi K | AE9: Female | AF9: IT | AG9: Manager | AH9: Bengaluru | AI9: 43227 | AJ9: 30981 | AK9: 86020 | AL9: 12396 | AM9: 13543 | AN9: 111959 | AO9: 1343508 | AP9: 0.15744013 | AQ9: 11 | AR9: 87 | AS9: 4 | AT9: 34 | AU9: 14 | AV9: 86 | AW9: 0 | AX9: No | AY9: No | AZ9: Manoj P
C10: E1018 | D10: Rahul S | E10: Female | F10: HR | G10: Manager | H10: Chennai | I10: 43903 | J10: 37480 | K10: 62841 | L10: 14562 | M10: 10504 | N10: 87907 | O10: 1054884 | P10: 0.16715202 | Q10: 1 | R10: 90 | S10: 4 | T10: 29 | U10: 22 | V10: 54 | W10: 0 | X10: No | Y10: No | Z10: Manoj P | AC10: E1018 | AD10: Rahul S | AE10: Female | AF10: HR | AG10: Manager | AH10: Chennai | AI10: 43903 | AJ10: 37480 | AK10: 62841 | AL10: 14562 | AM10: 10504 | AN10: 87907 | AO10: 1054884 | AP10: 0.16715202 | AQ10: 1 | AR10: 90 | AS10: 4 | AT10: 29 | AU10: 22 | AV10: 54 | AW10: 0 | AX10: No | AY10: No | AZ10: Manoj P
C11: E1023 | D11: Anitha M | E11: Male | F11: Marketing | G11: Associate | H11: Bengaluru | I11: 43605 | J11: 32316 | K11: 76129 | L11: 4262 | M11: 9141 | N11: 89532 | O11: 1074384 | P11: 0.12007251 | Q11: 2 | R11: 89 | S11: 2 | T11: 60 | U11: 23 | V11: 96 | W11: 0 | X11: Yes | Y11: No | Z11: Lakshmi S | AC11: E1023 | AD11: Anitha M | AE11: Male | AF11: Marketing | AG11: Associate | AH11: Bengaluru | AI11: 43605 | AJ11: 32316 | AK11: 76129 | AL11: 4262 | AM11: 9141 | AN11: 89532 | AO11: 1074384 | AP11: 0.12007251 | AQ11: 2 | AR11: 89 | AS11: 2 | AT11: 60 | AU11: 23 | AV11: 96 | AW11: 0 | AX11: Yes | AY11: No | AZ11: Lakshmi S
C12: E1024 | D12: Divya M | E12: Female | F12: Marketing | G12: Manager | H12: Chennai | I12: 43827 | J12: 37754 | K12: 71269 | L12: 7730 | M12: 6943 | N12: 85942 | O12: 1031304 | P12: 0.097419635 | Q12: 7 | R12: 92 | S12: 1 | T12: 13 | U12: 16 | V12: 98 | W12: 0 | X12: Yes | Y12: No | Z12: Karthik V | AC12: E1024 | AD12: Divya M | AE12: Female | AF12: Marketing | AG12: Manager | AH12: Chennai | AI12: 43827 | AJ12: 37754 | AK12: 71269 | AL12: 7730 | AM12: 6943 | AN12: 85942 | AO12: 1031304 | AP12: 0.097419635 | AQ12: 7 | AR12: 92 | AS12: 1 | AT12: 13 | AU12: 16 | AV12: 98 | AW12: 0 | AX12: Yes | AY12: No | AZ12: Karthik V
C13: E1027 | D13: Pooja S | E13: Male | F13: IT | G13: Associate | H13: Chennai | I13: 43199 | J13: 34584 | K13: 77522 | L13: 8661 | M13: 13892 | N13: 100075 | O13: 1200900 | P13: 0.17920074 | Q13: 8 | R13: 81 | S13: 1 | T13: 70 | U13: 2 | V13: 57 | W13: 0 | X13: No | Y13: No | Z13: Manoj P | AC13: E1027 | AD13: Pooja S | AE13: Male | AF13: IT | AG13: Associate | AH13: Chennai | AI13: 43199 | AJ13: 34584 | AK13: 77522 | AL13: 8661 | AM13: 13892 | AN13: 100075 | AO13: 1200900 | AP13: 0.17920074 | AQ13: 8 | AR13: 81 | AS13: 1 | AT13: 70 | AU13: 2 | AV13: 57 | AW13: 0 | AX13: No | AY13: No | AZ13: Manoj P
... C94: E1199 | D94: Nisha M | E94: Female | F94: HR | G94: Senior Analyst | H94: Madurai | I94: 45524 | J94: 31983 | K94: 83226 | L94: 4643 | M94: 3808 | N94: 91677 | O94: 1100124 | P94: 0.045754932 | Q94: 10 | R94: 87 | S94: 2 | T94: 30 | U94: 19 | V94: 78 | W94: 0 | X94: No | Y94: No | Z94: Divya R | AC94: E1199 | AD94: Nisha M | AE94: Female | AF94: HR | AG94: Senior Analyst | AH94: Madurai | AI94: 45524 | AJ94: 31983 | AK94: 83226 | AL94: 4643 | AM94: 3808 | AN94: 91677 | AO94: 1100124 | AP94: 0.045754932 | AQ94: 10 | AR94: 87 | AS94: 2 | AT94: 30 | AU94: 19 | AV94: 78 | AW94: 0 | AX94: No | AY94: No | AZ94: Divya R

Sheet Q20
A1: 20 | B1: Calculate the average performance score of employees. | C1: =AVERAGE(emp_data!T2:T201) -> 75.735

Sheet Q21
A1: 21 | B1: Identify the employee with the highest performance score. | C1: =_xlfn.LET( _xlpm.Score,emp_data!T2:T201, _xlpm.EmpName,emp_data!B2:B201, INDEX(_xlpm.EmpName,MATCH(MAX(_xlpm.Score),_xlpm.Score,0)) ) -> Asha K
C4: =_xlfn.LET(_xlpm.score,emp_data!T2:T201,_xlpm.emp_name,emp_data!B2:B201,INDEX(_xlpm.emp_name,MATCH(MAX(_xlpm.score),_xlpm.score,0))) -> Asha K

Sheet Q22
A1: 22 | B1: Identify the employee with the lowest performance score. | C1: =_xlfn.LET( _xlpm.Score,emp_data!T2:T201, _xlpm.EmpName,emp_data!B2:B201, INDEX(_xlpm.EmpName,MATCH(MIN(_xlpm.Score),_xlpm.Score,0)) ) -> Priya V
C4: =_xlfn.LET(_xlpm.score,emp_data!T2:T201,_xlpm.emp_name,emp_data!B2:B201,INDEX(_xlpm.emp_name,MATCH(MIN(_xlpm.score),_xlpm.score,0))) -> Priya V

Sheet Q23
C1: Given %
A2: 23 | B2: Classify employees as Top Performer if their Rating is above the given % | C2: 100 | D2: {=_xlfn.LET(_xlpm.emp_id, emp_data!A2:A201, _xlpm.rating, emp_data!T2:T201, _xlfn._xlws.FILTER(_xlpm.emp_id & " - " &_xlpm.rating & " %", _xlpm.rating>=C2,"No Top Performer"))} -> E1031 - 100 %
D3: E1065 - 100 %
D4: E1173 - 100 %
D5: E1189 - 100 %
C7: 100

Sheet Q24
C1: Given %
A2: 24 | B2: Identify employees eligible for appreciation based on Attendance greater than given %. | C2: 80 | D2: {=_xlfn.LET(_xlpm.emp_id, emp_data!A2:A201, _xlpm.att, emp_data!P2:P201, _xlfn._xlws.FILTER(_xlpm.emp_id & " - " & _xlpm.att & " % ", _xlpm.att>=C2, "Not Regular"))} -> E1001 - 90 % | E2: {=_xlfn.LET(_xlpm.emp_id,emp_data!A2:A201,_xlpm.emp_name,emp_data!B2:B201,_xlpm.att,emp_data!P2:P201,_xlfn._xlws.FILTER(_xlpm.emp_id & "-" & _xlpm.emp_name & "-" & _xlpm.att & "%",_xlpm.att>=C2,"not regular"))} -> E1001-Priya S-90%
D3: E1002 - 83 % | E3: E1002-Anitha R-83%
D4: E1003 - 86 % | E4: E1003-Meena M-86%
D5: E1004 - 82 % | E5: E1004-Manoj M-82%
D6: E1005 - 80 % | E6: E1005-Kumar K-80%
D7: E1006 - 94 % | E7: E1006-Priya V-94%
D8: E1007 - 96 % | E8: E1007-Vijay K-96%
D9: E1008 - 80 % | E9: E1008-Kumar K-80%
D10: E1009 - 92 % | E10: E1009-Anitha V-92%
D11: E1010 - 89 % | E11: E1010-Sneha P-89%
D12: E1011 - 82 % | E12: E1011-Manoj P-82%
D13: E1012 - 82 % | E13: E1012-Kumar K-82%
D14: E1013 - 95 % | E14: E1013-Rahul P-95%
... D201: E1200 - 94 % | E201: E1200-Meena K-94%

Sheet Q25
A1: 25 | B1: Calculate the average attendance percentage. | C1: =AVERAGE(emp_data!P2:P201) -> 89.345

Sheet Q26
A1: 26 | B1: Identify employees with attendance below 80%. | C1: {=_xlfn.LET(_xlpm.emp_id, emp_data!A2:A201, _xlpm.att, emp_data!P2:P201, _xlfn._xlws.FILTER(_xlpm.emp_id & " - " & _xlpm.att & " % ", _xlpm.att<=80, "Not Regular"))} -> E1005 - 80 %
C2: E1008 - 80 %
C3: E1025 - 80 %
C4: E1030 - 80 %
C5: E1087 - 80 %
C6: E1095 - 80 %
C7: E1140 - 80 %
C8: E1143 - 80 %
C9: E1164 - 80 %
C10: E1171 - 80 %
A16: 27 | B16: Find employees having both excellent attendance and excellent performance. | C16: {=_xlfn.LET(_xlpm.emp_id, emp_data!A2:A201, _xlpm.att, emp_data!P2:P201, _xlpm.performance, emp_data!T2:T201, _xlfn._xlws.FILTER(_xlpm.emp_id & "- Performance : " & _xlpm.performance & " % - Attendance : " &_xlpm.att & " %", (_xlpm.att>95) * (_xlpm.performance>=95), "No Employees Found"))} -> E1115- Performance : 99 % - Attendance : 96 %
C17: E1151- Performance : 95 % - Attendance : 98 %

Sheet Q27
A1: 27 | B1: Find employees having both excellent attendance and excellent performance. | C1: {=_xlfn.LET(_xlpm.emp_id, emp_data!A2:A201, _xlpm.att, emp_data!P2:P201, _xlpm.performance, emp_data!T2:T201, _xlfn._xlws.FILTER(_xlpm.emp_id & "- Performance : " & _xlpm.performance & " % - Attendance : " &_xlpm.att & " %", (_xlpm.att>95) * (_xlpm.performance>=95), "No Employees Found"))} -> E1115- Performance : 99 % - Attendance : 96 %
C2: E1151- Performance : 95 % - Attendance : 98 %

Sheet Q28
A1: Calculate the average employee experience. | B1: =AVERAGE(emp_data!O2:O201) -> 10.66 | C1: Years

Sheet Q29
B1: Years of Experience
A2: Identify employees having more than or equal to given years of experience. | B2: 18 | C2: {=_xlfn.LET(_xlpm.emp_id, emp_data!A2:A201, _xlpm.experience, emp_data!O2:O201, _xlfn._xlws.FILTER(_xlpm.emp_id & ": Experience - " & _xlpm.experience & " Years",(_xlpm.experience>=B2),"No Employee Found"))} -> E1006: Experience - 18 Years
C3: E1013: Experience - 19 Years
C4: E1029: Experience - 20 Years
C5: E1036: Experience - 18 Years
C6: E1041: Experience - 20 Years
C7: E1052: Experience - 20 Years
C8: E1054: Experience - 20 Years
C9: E1071: Experience - 19 Years
C10: E1074: Experience - 18 Years
C11: E1082: Experience - 18 Years
C12: E1085: Experience - 19 Years
C13: E1087: Experience - 20 Years
C14: E1091: Experience - 18 Years
... C35: E1200: Experience - 19 Years

Sheet Q30
B1: Years of Experince
A2: Identify newly hired employees with less than given years of experience. | B2: 1 | C2: {=_xlfn.LET(_xlpm.emp_id, emp_data!A2:A201, _xlpm.experience, emp_data!O2:O201, _xlfn._xlws.FILTER(_xlpm.emp_id & ": Experience - " & _xlpm.experience & " Years", (_xlpm.experience<='Q30'!B2),"No Employee Found"))} -> E1018: Experience - 1 Years
C3: E1058: Experience - 1 Years
C4: E1063: Experience - 1 Years
C5: E1067: Experience - 1 Years
C6: E1073: Experience - 1 Years
C7: E1075: Experience - 1 Years
C8: E1081: Experience - 1 Years
C9: E1089: Experience - 1 Years
C10: E1103: Experience - 1 Years
C11: E1124: Experience - 1 Years
C12: E1131: Experience - 1 Years
C13: E1137: Experience - 1 Years
C14: E1168: Experience - 1 Years
C15: E1169: Experience - 1 Years
